# AwaitTaskWithException
Run a task that throws an exception

Do something

await task
